#VRML_SIM R2025a utf8

EXTERNPROTO "https://raw.githubusercontent.com/cyberbotics/webots/R2025a/projects/objects/backgrounds/protos/TexturedBackground.proto"
EXTERNPROTO "https://raw.githubusercontent.com/cyberbotics/webots/R2025a/projects/objects/backgrounds/protos/TexturedBackgroundLight.proto"
EXTERNPROTO "https://raw.githubusercontent.com/cyberbotics/webots/R2025a/projects/objects/floors/protos/RectangleArena.proto"
EXTERNPROTO "https://raw.githubusercontent.com/cyberbotics/webots/R2025a/projects/appearances/protos/Parquetry.proto"
EXTERNPROTO "https://raw.githubusercontent.com/cyberbotics/webots/R2025a/projects/objects/balls/protos/Ball.proto"

WorldInfo {
  basicTimeStep 8
  contactProperties [
    ContactProperties {
      material1 "foot"
      coulombFriction [
        4
      ]
    }
    ContactProperties {
      material1 "stabilizer"
      coulombFriction [
        0.2
      ]
    }
  ]
}
Viewpoint {
  orientation 0.13400046175546673 0.3442925743155359 -0.9292505041809247 0.8959232718096751
  position -1.2350834468499463 1.0475050829165586 0.63705669218504
}
TexturedBackground {
}
TexturedBackgroundLight {
}
RectangleArena {
  floorSize 2 2
  floorAppearance Parquetry {
    type "light strip"
  }
}
DEF LIVMACH_WALKER Robot {
  translation 0 0 0.094
  children [
    Shape {
      appearance Appearance {
        material Material {
          diffuseColor 0.28 0.28 0.3
        }
      }
      geometry Box {
        size 0.132 0.083 0.039
      }
    }
    Pose {
      translation 0.05 0 -0.022
      children [
        Shape {
          appearance Appearance {
            material Material {
              diffuseColor 0.08 0.08 0.08
            }
          }
          geometry Sphere {
            radius 0.009
          }
        }
      ]
    }
    Pose {
      translation -0.05 0 -0.022
      children [
        Shape {
          appearance Appearance {
            material Material {
              diffuseColor 0.08 0.08 0.08
            }
          }
          geometry Sphere {
            radius 0.009
          }
        }
      ]
    }
    InertialUnit {
      name "imu"
    }
    HingeJoint {
      jointParameters HingeJointParameters {
        axis 0 1 0
        anchor 0.05 -0.041 -0.008
        minStop -1.5708
        maxStop 1.5708
        dampingConstant 0.05
      }
      device [
        RotationalMotor {
          name "front_left_leg_motor"
          maxTorque 4
        }
        PositionSensor {
          name "front_left_leg_sensor"
        }
      ]
      endPoint Solid {
        translation 0.05 -0.041 -0.05
        rotation 0 1 0 0
        children [
          Pose {
            translation 0 0 0.002
            children [
              Shape {
                appearance Appearance {
                  material Material {
                    diffuseColor 0.84 0.26 0.26
                  }
                }
                geometry Box {
                  size 0.02 0.014 0.06
                }
              }
            ]
          }
          Pose {
            translation 0.028 0 -0.03
            children [
              Shape {
                appearance Appearance {
                  material Material {
                    diffuseColor 0.12 0.12 0.12
                  }
                }
                geometry Box {
                  size 0.08 0.022 0.01
                }
              }
            ]
          }
        ]
        name "front_left_leg"
        contactMaterial "foot"
        boundingObject Group {
          children [
            Pose {
              translation 0 0 0.002
              children [
                Box {
                  size 0.02 0.014 0.06
                }
              ]
            }
            Pose {
              translation 0.028 0 -0.03
              children [
                Box {
                  size 0.08 0.022 0.01
                }
              ]
            }
          ]
        }
        physics Physics {
          density -1
          mass 0.012
        }
      }
    }
    HingeJoint {
      jointParameters HingeJointParameters {
        axis 0 1 0
        anchor 0.05 0.041 -0.008
        minStop -1.5708
        maxStop 1.5708
        dampingConstant 0.05
      }
      device [
        RotationalMotor {
          name "front_right_leg_motor"
          maxTorque 4
        }
        PositionSensor {
          name "front_right_leg_sensor"
        }
      ]
      endPoint Solid {
        translation 0.05 0.041 -0.05
        rotation 0 1 0 0
        children [
          Pose {
            translation 0 0 0.002
            children [
              Shape {
                appearance Appearance {
                  material Material {
                    diffuseColor 0.84 0.58 0.5
                  }
                }
                geometry Box {
                  size 0.02 0.014 0.06
                }
              }
            ]
          }
          Pose {
            translation 0.028 0 -0.03
            children [
              Shape {
                appearance Appearance {
                  material Material {
                    diffuseColor 0.12 0.12 0.12
                  }
                }
                geometry Box {
                  size 0.08 0.022 0.01
                }
              }
            ]
          }
        ]
        name "front_right_leg"
        contactMaterial "foot"
        boundingObject Group {
          children [
            Pose {
              translation 0 0 0.002
              children [
                Box {
                  size 0.02 0.014 0.06
                }
              ]
            }
            Pose {
              translation 0.028 0 -0.03
              children [
                Box {
                  size 0.08 0.022 0.01
                }
              ]
            }
          ]
        }
        physics Physics {
          density -1
          mass 0.012
        }
      }
    }
    HingeJoint {
      jointParameters HingeJointParameters {
        axis 0 1 0
        anchor -0.05 -0.041 -0.008
        minStop -1.5708
        maxStop 1.5708
        dampingConstant 0.05
      }
      device [
        RotationalMotor {
          name "rear_left_leg_motor"
          maxTorque 4
        }
        PositionSensor {
          name "rear_left_leg_sensor"
        }
      ]
      endPoint Solid {
        translation -0.05 -0.041 -0.05
        rotation 0 1 0 0
        children [
          Pose {
            translation 0 0 0.002
            children [
              Shape {
                appearance Appearance {
                  material Material {
                    diffuseColor 0.26 0.6 0.84
                  }
                }
                geometry Box {
                  size 0.02 0.014 0.06
                }
              }
            ]
          }
          Pose {
            translation -0.028 0 -0.03
            children [
              Shape {
                appearance Appearance {
                  material Material {
                    diffuseColor 0.12 0.12 0.12
                  }
                }
                geometry Box {
                  size 0.08 0.022 0.01
                }
              }
            ]
          }
        ]
        name "rear_left_leg"
        contactMaterial "foot"
        boundingObject Group {
          children [
            Pose {
              translation 0 0 0.002
              children [
                Box {
                  size 0.02 0.014 0.06
                }
              ]
            }
            Pose {
              translation -0.028 0 -0.03
              children [
                Box {
                  size 0.08 0.022 0.01
                }
              ]
            }
          ]
        }
        physics Physics {
          density -1
          mass 0.012
        }
      }
    }
    HingeJoint {
      jointParameters HingeJointParameters {
        axis 0 1 0
        anchor -0.05 0.041 -0.008
        minStop -1.5708
        maxStop 1.5708
        dampingConstant 0.05
      }
      device [
        RotationalMotor {
          name "rear_right_leg_motor"
          maxTorque 4
        }
        PositionSensor {
          name "rear_right_leg_sensor"
        }
      ]
      endPoint Solid {
        translation -0.05 0.041 -0.05
        rotation 0 1 0 0
        children [
          Pose {
            translation 0 0 0.002
            children [
              Shape {
                appearance Appearance {
                  material Material {
                    diffuseColor 0.74 0.72 0.28
                  }
                }
                geometry Box {
                  size 0.02 0.014 0.06
                }
              }
            ]
          }
          Pose {
            translation -0.028 0 -0.03
            children [
              Shape {
                appearance Appearance {
                  material Material {
                    diffuseColor 0.12 0.12 0.12
                  }
                }
                geometry Box {
                  size 0.08 0.022 0.01
                }
              }
            ]
          }
        ]
        name "rear_right_leg"
        contactMaterial "foot"
        boundingObject Group {
          children [
            Pose {
              translation 0 0 0.002
              children [
                Box {
                  size 0.02 0.014 0.06
                }
              ]
            }
            Pose {
              translation -0.028 0 -0.03
              children [
                Box {
                  size 0.08 0.022 0.01
                }
              ]
            }
          ]
        }
        physics Physics {
          density -1
          mass 0.012
        }
      }
    }
  ]
  name "livmach_walker"
  contactMaterial "stabilizer"
  boundingObject Group {
    children [
      Pose {
        translation 0 0 0.004
        children [
          Box {
            size 0.132 0.083 0.03
          }
        ]
      }
      Pose {
        translation 0.05 0 -0.022
        children [
          Sphere {
            radius 0.009
          }
        ]
      }
      Pose {
        translation -0.05 0 -0.022
        children [
          Sphere {
            radius 0.009
          }
        ]
      }
    ]
  }
  physics Physics {
    density -1
    mass 0.07
  }
  controller "livmach_walker"
}
Ball {
  translation -0.22 0 0.0525
  color 0.164706 0.333333 0.498039
  radius 0.05
}
