#VRML_SIM R2025a utf8

EXTERNPROTO "https://raw.githubusercontent.com/cyberbotics/webots/R2025a/projects/objects/backgrounds/protos/TexturedBackground.proto"
EXTERNPROTO "https://raw.githubusercontent.com/cyberbotics/webots/R2025a/projects/objects/backgrounds/protos/TexturedBackgroundLight.proto"
EXTERNPROTO "https://raw.githubusercontent.com/cyberbotics/webots/R2025a/projects/objects/floors/protos/RectangleArena.proto"

WorldInfo {
}
Viewpoint {
  orientation 0.1556571405899007 -0.0037044823115183804 -0.987804196890345 3.2521662909348215
  position 0.9047383213504985 -0.19347119563438378 0.3935311099453063
}
TexturedBackground {
}
TexturedBackgroundLight {
}
RectangleArena {
  floorSize 5 5
}
Robot {
  translation 0 0 0.0506814
  children [
    DEF Base Shape {
      appearance PBRAppearance {
        baseColor 1 0.4 0.5
        metalness 0
      }
      geometry Box {
        size 0.1 0.2 0.1
      }
    }
    HingeJoint {
      jointParameters HingeJointParameters {
        position 917.5803304515731
        axis 0 0 -1
        anchor 0 0.055 0.055
      }
      device [
        RotationalMotor {
          name "Right_motor"
          maxVelocity 200
        }
      ]
      endPoint Solid {
        translation -2.051876616533773e-10 0.05499999995328805 0.05499876737163286
        rotation 0 0 -1 0.2352756033534777
        children [
          DEF Wheel Shape {
            appearance PBRAppearance {
              baseColor 0 1 0
              roughness 1
              metalness 0
            }
            geometry Cylinder {
              height 0.01
              radius 0.05
            }
          }
        ]
        boundingObject USE Wheel
        physics DEF wheel_physics Physics {
        }
      }
    }
    HingeJoint {
      jointParameters HingeJointParameters {
        position -906.6218490604899
        axis 0 0 -1
        anchor 0 -0.055 0.055
      }
      device [
        RotationalMotor {
          name "Left_motor"
          maxVelocity 200
        }
      ]
      endPoint Solid {
        translation -3.90705676701772e-11 -0.05500000020677882 0.05499876737163282
        rotation 0 0 1 1.8431648266294691
        children [
          USE Wheel
        ]
        name "solid(1)"
        boundingObject USE Wheel
        physics USE wheel_physics
      }
    }
  ]
  name "solid"
  boundingObject USE Base
  physics Physics {
    density 7.874
  }
  controller "my_Shooter_controller"
}
Solid {
  translation 0 0 0.105
  children [
    DEF Projectile Shape {
      appearance PBRAppearance {
        baseColor 1 0 0
        roughness 1
        metalness 0
      }
      geometry Sphere {
        radius 0.006
      }
    }
  ]
  name "projectile"
  boundingObject USE Projectile
  physics Physics {
    density 1.1
  }
}
